2023-06-06 15:38:50,453 INFO    StreamThr :26033 [internal.py:wandb_internal():86] W&B internal server running at pid: 26033, started at: 2023-06-06 15:38:50.451909
2023-06-06 15:38:50,457 DEBUG   HandlerThread:26033 [handler.py:handle_request():144] handle_request: status
2023-06-06 15:38:50,458 INFO    WriterThread:26033 [datastore.py:open_for_write():85] open: /workspaces/mlops-zoomcamp/cohorts/2023/02-experiment-tracking/homework-wandb/wandb/run-20230606_153850-9dt6nxnn/run-9dt6nxnn.wandb
2023-06-06 15:38:50,460 DEBUG   SenderThread:26033 [sender.py:send():375] send: header
2023-06-06 15:38:50,465 DEBUG   SenderThread:26033 [sender.py:send():375] send: run
2023-06-06 15:38:50,577 ERROR   SenderThread:26033 [internal_api.py:execute():288] 404 response executing GraphQL.
2023-06-06 15:38:50,577 ERROR   SenderThread:26033 [internal_api.py:execute():289] {"errors":[{"message":"entity avinaschandrav not found during upsertBucket","path":["upsertBucket"]}],"data":{"upsertBucket":null}}
2023-06-06 15:38:50,579 ERROR   SenderThread:26033 [sender.py:send_run():979] It appears that you do not have permission to access the requested resource. Please reach out to the project owner to grant you access. If you have the correct permissions, verify that there are no issues with your networking setup.(Error 404: Not Found)
Traceback (most recent call last):
  File "/usr/local/python/3.10.4/lib/python3.10/site-packages/wandb/sdk/lib/retry.py", line 131, in __call__
    result = self._call_fn(*args, **kwargs)
  File "/usr/local/python/3.10.4/lib/python3.10/site-packages/wandb/sdk/internal/internal_api.py", line 285, in execute
    return self.client.execute(*args, **kwargs)  # type: ignore
  File "/usr/local/python/3.10.4/lib/python3.10/site-packages/wandb/vendor/gql-0.2.0/wandb_gql/client.py", line 52, in execute
    result = self._get_result(document, *args, **kwargs)
  File "/usr/local/python/3.10.4/lib/python3.10/site-packages/wandb/vendor/gql-0.2.0/wandb_gql/client.py", line 60, in _get_result
    return self.transport.execute(document, *args, **kwargs)
  File "/usr/local/python/3.10.4/lib/python3.10/site-packages/wandb/sdk/lib/gql_request.py", line 56, in execute
    request.raise_for_status()
  File "/home/codespace/.local/lib/python3.10/site-packages/requests/models.py", line 1021, in raise_for_status
    raise HTTPError(http_error_msg, response=self)
requests.exceptions.HTTPError: 404 Client Error: Not Found for url: https://api.wandb.ai/graphql

During handling of the above exception, another exception occurred:

Traceback (most recent call last):
  File "/usr/local/python/3.10.4/lib/python3.10/site-packages/wandb/sdk/internal/sender.py", line 977, in send_run
    self._init_run(run, config_value_dict)
  File "/usr/local/python/3.10.4/lib/python3.10/site-packages/wandb/sdk/internal/sender.py", line 1015, in _init_run
    server_run, inserted, server_messages = self._api.upsert_run(
  File "/usr/local/python/3.10.4/lib/python3.10/site-packages/wandb/apis/normalize.py", line 73, in wrapper
    raise err
  File "/usr/local/python/3.10.4/lib/python3.10/site-packages/wandb/apis/normalize.py", line 41, in wrapper
    return func(*args, **kwargs)
  File "/usr/local/python/3.10.4/lib/python3.10/site-packages/wandb/sdk/internal/internal_api.py", line 1690, in upsert_run
    response = self.gql(
  File "/usr/local/python/3.10.4/lib/python3.10/site-packages/wandb/sdk/internal/internal_api.py", line 257, in gql
    ret = self._retry_gql(
  File "/usr/local/python/3.10.4/lib/python3.10/site-packages/wandb/sdk/lib/retry.py", line 147, in __call__
    retry_timedelta_triggered = check_retry_fn(e)
  File "/usr/local/python/3.10.4/lib/python3.10/site-packages/wandb/util.py", line 907, in check_retry_fn
    return fallback_retry_fn(e)
  File "/usr/local/python/3.10.4/lib/python3.10/site-packages/wandb/util.py", line 849, in no_retry_auth
    raise CommError(
wandb.errors.CommError: It appears that you do not have permission to access the requested resource. Please reach out to the project owner to grant you access. If you have the correct permissions, verify that there are no issues with your networking setup.(Error 404: Not Found)
2023-06-06 15:38:50,654 DEBUG   HandlerThread:26033 [handler.py:handle_request():144] handle_request: shutdown
2023-06-06 15:38:50,654 INFO    HandlerThread:26033 [handler.py:finish():842] shutting down handler
2023-06-06 15:38:51,465 INFO    WriterThread:26033 [datastore.py:close():298] close: /workspaces/mlops-zoomcamp/cohorts/2023/02-experiment-tracking/homework-wandb/wandb/run-20230606_153850-9dt6nxnn/run-9dt6nxnn.wandb
2023-06-06 15:38:51,584 INFO    SenderThread:26033 [sender.py:finish():1550] shutting down sender
